2025-08-19 22:37:25,243 - ERROR - خطا در اجرای فرآیند مغایرت‌گیری: ReconciliationProcess.__init__() missing 1 required positional argument: 'manual_reconciliation_queue'
2025-08-20 21:34:57 - main - ERROR - خطای رابط کاربری:
2025-08-20 21:34:57 - main - ERROR - Traceback (most recent call last):
  File "C:\Users\Hossein\AppData\Local\Programs\Python\Python313\Lib\tkinter\__init__.py", line 2068, in __call__
    return self.func(*args)
           ~~~~~~~~~^^^^^^^
  File "e:\Work Space\Reconciliation\ui\dialog\manual_reconciliation_dialog.py", line 287, in on_deduct_fee
    fee_note = f"کارمزد تراکنش {self.bank_record['tracking_number']} به مبلغ {fee_amount:,}"
                                ~~~~~~~~~~~~~~~~^^^^^^^^^^^^^^^^^^^
KeyError: 'tracking_number'

2025-08-20 21:35:27 - main - ERROR - خطای رابط کاربری:
2025-08-20 21:35:27 - main - ERROR - Traceback (most recent call last):
  File "C:\Users\Hossein\AppData\Local\Programs\Python\Python313\Lib\tkinter\__init__.py", line 2068, in __call__
    return self.func(*args)
           ~~~~~~~~~^^^^^^^
  File "e:\Work Space\Reconciliation\ui\dialog\manual_reconciliation_dialog.py", line 287, in on_deduct_fee
    fee_note = f"کارمزد تراکنش {self.bank_record['tracking_number']} به مبلغ {fee_amount:,}"
                                ~~~~~~~~~~~~~~~~^^^^^^^^^^^^^^^^^^^
KeyError: 'tracking_number'

2025-08-20 21:35:41 - main - ERROR - خطای رابط کاربری:
2025-08-20 21:35:41 - main - ERROR - Traceback (most recent call last):
  File "C:\Users\Hossein\AppData\Local\Programs\Python\Python313\Lib\tkinter\__init__.py", line 2068, in __call__
    return self.func(*args)
           ~~~~~~~~~^^^^^^^
  File "e:\Work Space\Reconciliation\ui\dialog\manual_reconciliation_dialog.py", line 287, in on_deduct_fee
    fee_note = f"کارمزد تراکنش {self.bank_record['tracking_number']} به مبلغ {fee_amount:,}"
                                ~~~~~~~~~~~~~~~~^^^^^^^^^^^^^^^^^^^
KeyError: 'tracking_number'

2025-08-20 21:35:53 - main - ERROR - خطای رابط کاربری:
2025-08-20 21:35:53 - main - ERROR - Traceback (most recent call last):
  File "C:\Users\Hossein\AppData\Local\Programs\Python\Python313\Lib\tkinter\__init__.py", line 2068, in __call__
    return self.func(*args)
           ~~~~~~~~~^^^^^^^
  File "e:\Work Space\Reconciliation\ui\dialog\manual_reconciliation_dialog.py", line 287, in on_deduct_fee
    fee_note = f"کارمزد تراکنش {self.bank_record['tracking_number']} به مبلغ {fee_amount:,}"
                                ~~~~~~~~~~~~~~~~^^^^^^^^^^^^^^^^^^^
KeyError: 'tracking_number'

2025-08-20 22:04:49 - main - ERROR - خطا در بارگذاری تب مغایرت‌یابی دستی: No item with that key
2025-08-20 22:04:49 - main - CRITICAL - خطای بحرانی در اجرای برنامه: No item with that key
2025-08-20 22:04:49 - main - CRITICAL - جزئیات خطا:
Traceback (most recent call last):
  File "E:\Work Space\Reconciliation\main.py", line 120, in main
    manual_reconciliation_tab = ManualReconciliationTab(notebook)
  File "E:\Work Space\Reconciliation\ui\manual_reconciliation_tab.py", line 46, in __init__
    self.load_banks_to_combobox()
    ~~~~~~~~~~~~~~~~~~~~~~~~~~~^^
  File "E:\Work Space\Reconciliation\ui\manual_reconciliation_tab.py", line 213, in load_banks_to_combobox
    bank_names = [bank['name'] for bank in banks]
                  ~~~~^^^^^^^^
IndexError: No item with that key

2025-08-21 22:09:22 - reconciliation.mellat_paid_transfer_reconciliation - ERROR - Error reconciling Bank Transfer 40: 'tracking_number'
Traceback (most recent call last):
  File "e:\Work Space\Reconciliation\reconciliation\mellat_reconciliation\mellat_paid_transfer_reconciliation.py", line 129, in _reconcile_single_transfer
    'description': f'Bank fee for transfer {bank_record["tracking_number"]}',
                                            ~~~~~~~~~~~^^^^^^^^^^^^^^^^^^^
KeyError: 'tracking_number'
2025-08-21 22:09:22,193 - ERROR - Error reconciling Bank Transfer 40: 'tracking_number'
Traceback (most recent call last):
  File "e:\Work Space\Reconciliation\reconciliation\mellat_reconciliation\mellat_paid_transfer_reconciliation.py", line 129, in _reconcile_single_transfer
    'description': f'Bank fee for transfer {bank_record["tracking_number"]}',
                                            ~~~~~~~~~~~^^^^^^^^^^^^^^^^^^^
KeyError: 'tracking_number'
2025-08-21 22:10:03 - reconciliation.mellat_paid_transfer_reconciliation - ERROR - Error reconciling Bank Transfer 41: 'tracking_number'
Traceback (most recent call last):
  File "e:\Work Space\Reconciliation\reconciliation\mellat_reconciliation\mellat_paid_transfer_reconciliation.py", line 129, in _reconcile_single_transfer
    'description': f'Bank fee for transfer {bank_record["tracking_number"]}',
                                            ~~~~~~~~~~~^^^^^^^^^^^^^^^^^^^
KeyError: 'tracking_number'
2025-08-21 22:10:03,338 - ERROR - Error reconciling Bank Transfer 41: 'tracking_number'
Traceback (most recent call last):
  File "e:\Work Space\Reconciliation\reconciliation\mellat_reconciliation\mellat_paid_transfer_reconciliation.py", line 129, in _reconcile_single_transfer
    'description': f'Bank fee for transfer {bank_record["tracking_number"]}',
                                            ~~~~~~~~~~~^^^^^^^^^^^^^^^^^^^
KeyError: 'tracking_number'
2025-08-21 22:10:09 - reconciliation.mellat_paid_transfer_reconciliation - ERROR - Error reconciling Bank Transfer 42: 'tracking_number'
Traceback (most recent call last):
  File "e:\Work Space\Reconciliation\reconciliation\mellat_reconciliation\mellat_paid_transfer_reconciliation.py", line 129, in _reconcile_single_transfer
    'description': f'Bank fee for transfer {bank_record["tracking_number"]}',
                                            ~~~~~~~~~~~^^^^^^^^^^^^^^^^^^^
KeyError: 'tracking_number'
2025-08-21 22:10:09,740 - ERROR - Error reconciling Bank Transfer 42: 'tracking_number'
Traceback (most recent call last):
  File "e:\Work Space\Reconciliation\reconciliation\mellat_reconciliation\mellat_paid_transfer_reconciliation.py", line 129, in _reconcile_single_transfer
    'description': f'Bank fee for transfer {bank_record["tracking_number"]}',
                                            ~~~~~~~~~~~^^^^^^^^^^^^^^^^^^^
KeyError: 'tracking_number'
2025-08-21 22:10:16 - reconciliation.mellat_paid_transfer_reconciliation - ERROR - Error reconciling Bank Transfer 64: 'tracking_number'
Traceback (most recent call last):
  File "e:\Work Space\Reconciliation\reconciliation\mellat_reconciliation\mellat_paid_transfer_reconciliation.py", line 129, in _reconcile_single_transfer
    'description': f'Bank fee for transfer {bank_record["tracking_number"]}',
                                            ~~~~~~~~~~~^^^^^^^^^^^^^^^^^^^
KeyError: 'tracking_number'
2025-08-21 22:10:16,988 - ERROR - Error reconciling Bank Transfer 64: 'tracking_number'
Traceback (most recent call last):
  File "e:\Work Space\Reconciliation\reconciliation\mellat_reconciliation\mellat_paid_transfer_reconciliation.py", line 129, in _reconcile_single_transfer
    'description': f'Bank fee for transfer {bank_record["tracking_number"]}',
                                            ~~~~~~~~~~~^^^^^^^^^^^^^^^^^^^
KeyError: 'tracking_number'
2025-08-21 22:10:23 - reconciliation.mellat_paid_transfer_reconciliation - ERROR - Error reconciling Bank Transfer 89: 'tracking_number'
Traceback (most recent call last):
  File "e:\Work Space\Reconciliation\reconciliation\mellat_reconciliation\mellat_paid_transfer_reconciliation.py", line 129, in _reconcile_single_transfer
    'description': f'Bank fee for transfer {bank_record["tracking_number"]}',
                                            ~~~~~~~~~~~^^^^^^^^^^^^^^^^^^^
KeyError: 'tracking_number'
2025-08-21 22:10:23,334 - ERROR - Error reconciling Bank Transfer 89: 'tracking_number'
Traceback (most recent call last):
  File "e:\Work Space\Reconciliation\reconciliation\mellat_reconciliation\mellat_paid_transfer_reconciliation.py", line 129, in _reconcile_single_transfer
    'description': f'Bank fee for transfer {bank_record["tracking_number"]}',
                                            ~~~~~~~~~~~^^^^^^^^^^^^^^^^^^^
KeyError: 'tracking_number'
2025-08-21 22:10:35 - reconciliation.mellat_paid_transfer_reconciliation - ERROR - Error reconciling Bank Transfer 109: 'tracking_number'
Traceback (most recent call last):
  File "e:\Work Space\Reconciliation\reconciliation\mellat_reconciliation\mellat_paid_transfer_reconciliation.py", line 129, in _reconcile_single_transfer
    'description': f'Bank fee for transfer {bank_record["tracking_number"]}',
                                            ~~~~~~~~~~~^^^^^^^^^^^^^^^^^^^
KeyError: 'tracking_number'
2025-08-21 22:10:35,244 - ERROR - Error reconciling Bank Transfer 109: 'tracking_number'
Traceback (most recent call last):
  File "e:\Work Space\Reconciliation\reconciliation\mellat_reconciliation\mellat_paid_transfer_reconciliation.py", line 129, in _reconcile_single_transfer
    'description': f'Bank fee for transfer {bank_record["tracking_number"]}',
                                            ~~~~~~~~~~~^^^^^^^^^^^^^^^^^^^
KeyError: 'tracking_number'
2025-08-21 22:10:43 - reconciliation.mellat_paid_transfer_reconciliation - ERROR - Error reconciling Bank Transfer 110: 'tracking_number'
Traceback (most recent call last):
  File "e:\Work Space\Reconciliation\reconciliation\mellat_reconciliation\mellat_paid_transfer_reconciliation.py", line 129, in _reconcile_single_transfer
    'description': f'Bank fee for transfer {bank_record["tracking_number"]}',
                                            ~~~~~~~~~~~^^^^^^^^^^^^^^^^^^^
KeyError: 'tracking_number'
2025-08-21 22:10:43,016 - ERROR - Error reconciling Bank Transfer 110: 'tracking_number'
Traceback (most recent call last):
  File "e:\Work Space\Reconciliation\reconciliation\mellat_reconciliation\mellat_paid_transfer_reconciliation.py", line 129, in _reconcile_single_transfer
    'description': f'Bank fee for transfer {bank_record["tracking_number"]}',
                                            ~~~~~~~~~~~^^^^^^^^^^^^^^^^^^^
KeyError: 'tracking_number'
2025-08-21 22:10:49 - reconciliation.mellat_paid_transfer_reconciliation - ERROR - Error reconciling Bank Transfer 112: 'tracking_number'
Traceback (most recent call last):
  File "e:\Work Space\Reconciliation\reconciliation\mellat_reconciliation\mellat_paid_transfer_reconciliation.py", line 129, in _reconcile_single_transfer
    'description': f'Bank fee for transfer {bank_record["tracking_number"]}',
                                            ~~~~~~~~~~~^^^^^^^^^^^^^^^^^^^
KeyError: 'tracking_number'
2025-08-21 22:10:49,302 - ERROR - Error reconciling Bank Transfer 112: 'tracking_number'
Traceback (most recent call last):
  File "e:\Work Space\Reconciliation\reconciliation\mellat_reconciliation\mellat_paid_transfer_reconciliation.py", line 129, in _reconcile_single_transfer
    'description': f'Bank fee for transfer {bank_record["tracking_number"]}',
                                            ~~~~~~~~~~~^^^^^^^^^^^^^^^^^^^
KeyError: 'tracking_number'
2025-08-21 22:12:40 - reconciliation.mellat_paid_transfer_reconciliation - ERROR - Error reconciling Bank Transfer 137: 'tracking_number'
Traceback (most recent call last):
  File "e:\Work Space\Reconciliation\reconciliation\mellat_reconciliation\mellat_paid_transfer_reconciliation.py", line 129, in _reconcile_single_transfer
    'description': f'Bank fee for transfer {bank_record["tracking_number"]}',
                                            ~~~~~~~~~~~^^^^^^^^^^^^^^^^^^^
KeyError: 'tracking_number'
2025-08-21 22:12:40,618 - ERROR - Error reconciling Bank Transfer 137: 'tracking_number'
Traceback (most recent call last):
  File "e:\Work Space\Reconciliation\reconciliation\mellat_reconciliation\mellat_paid_transfer_reconciliation.py", line 129, in _reconcile_single_transfer
    'description': f'Bank fee for transfer {bank_record["tracking_number"]}',
                                            ~~~~~~~~~~~^^^^^^^^^^^^^^^^^^^
KeyError: 'tracking_number'
